Workbook

Sheet MR Accrual
B1: Coresphere100 Technologies Pvt. Ltd.
B2: Monthly revenue (Accrual)
F3: Amount in INR
B4: Particulars | C4: For the month ended | D4: For the month ended | E4: For the month ended | F4: For the month ended | G4: For the month ended | H4: For the month ended | I4: For the month ended | J4: For the month ended
C5: 45748 | D5: 45748 | E5: 45778 | F5: 45809 | G5: 45839 | H5: 45870 | I5: 45901 | J5: 45931 | K5: Total
B6: Monthly Revenue from B2B subscribers (A) | D6: =SUM(D9:D45) | E6: =SUM(E9:E45) | F6: =SUM(F9:F45) | G6: =SUM(G9:G45) | H6: =SUM(H9:H45) | I6: =SUM(I9:I45) | J6: =SUM(J9:J45) | K6: =SUM(K9:K45)
B8: Annual Subscription
B9: Annual- Half Yearly Payment | D9: =SUMIF(Pivot!$A$45:$A$84,B9,Pivot!$B$45:$B$84)/118% | E9: =SUMIF(Pivot!$A$45:$A$84,B9,Pivot!$C$45:$C$84)/118% | F9: =SUMIF(Pivot!$A$45:$A$84,B9,Pivot!$D$45:$D$84)/118% | G9: =SUMIF(Pivot!$A$45:$A$84,B9,Pivot!$E$45:$E$84)/118% | H9: =SUMIF(Pivot!$A$45:$A$84,B9,Pivot!$F$45:$F$84)/118% | I9: =SUMIF(Pivot!$A$45:$A$84,B9,Pivot!$G$45:$G$84)/118% | J9: =SUMIF(Pivot!$A$45:$H$84,B9,Pivot!$H$45:$H$84)/118% | K9: =SUM(D9:J9)
B10: Annual subscription, Quarterly upfront | D10: =SUMIF(Pivot!$A$45:$A$84,B10,Pivot!$B$45:$B$84)/118% | E10: =SUMIF(Pivot!$A$45:$A$84,B10,Pivot!$C$45:$C$84)/118% | F10: =SUMIF(Pivot!$A$45:$A$84,B10,Pivot!$D$45:$D$84)/118% | G10: =SUMIF(Pivot!$A$45:$A$84,B10,Pivot!$E$45:$E$84)/118% | H10: =SUMIF(Pivot!$A$45:$A$84,B10,Pivot!$F$45:$F$84)/118% | I10: =SUMIF(Pivot!$A$45:$A$84,B10,Pivot!$G$45:$G$84)/118% | J10: =SUMIF(Pivot!$A$45:$H$84,B10,Pivot!$H$45:$H$84)/118% | K10: =SUM(D10:J10)
B11: Annual Upfront | D11: =SUMIF(Pivot!$A$45:$A$84,B11,Pivot!$B$45:$B$84)/118% | E11: =SUMIF(Pivot!$A$45:$A$84,B11,Pivot!$C$45:$C$84)/118% | F11: =SUMIF(Pivot!$A$45:$A$84,B11,Pivot!$D$45:$D$84)/118% | G11: =SUMIF(Pivot!$A$45:$A$84,B11,Pivot!$E$45:$E$84)/118% | H11: =SUMIF(Pivot!$A$45:$A$84,B11,Pivot!$F$45:$F$84)/118% | I11: =SUMIF(Pivot!$A$45:$A$84,B11,Pivot!$G$45:$G$84)/118% | J11: =SUMIF(Pivot!$A$45:$H$84,B11,Pivot!$H$45:$H$84)/118% | K11: =SUM(D11:J11)
B12: Annual-Monthly | D12: =SUMIF(Pivot!$A$45:$A$84,B12,Pivot!$B$45:$B$84)/118% | E12: =SUMIF(Pivot!$A$45:$A$84,B12,Pivot!$C$45:$C$84)/118% | F12: =SUMIF(Pivot!$A$45:$A$84,B12,Pivot!$D$45:$D$84)/118% | G12: =SUMIF(Pivot!$A$45:$A$84,B12,Pivot!$E$45:$E$84)/118% | H12: =SUMIF(Pivot!$A$45:$A$84,B12,Pivot!$F$45:$F$84)/118% | I12: =SUMIF(Pivot!$A$45:$A$84,B12,Pivot!$G$45:$G$84)/118% | J12: =SUMIF(Pivot!$A$45:$H$84,B12,Pivot!$H$45:$H$84)/118% | K12: =SUM(D12:J12)
B13: 2 Year- Upfront | D13: =SUMIF(Pivot!$A$45:$A$84,B13,Pivot!$B$45:$B$84)/118% | E13: =SUMIF(Pivot!$A$45:$A$84,B13,Pivot!$C$45:$C$84)/118% | F13: =SUMIF(Pivot!$A$45:$A$84,B13,Pivot!$D$45:$D$84)/118% | G13: =SUMIF(Pivot!$A$45:$A$84,B13,Pivot!$E$45:$E$84)/118% | H13: =SUMIF(Pivot!$A$45:$A$84,B13,Pivot!$F$45:$F$84)/118% | I13: =SUMIF(Pivot!$A$45:$A$84,B13,Pivot!$G$45:$G$84)/118% | J13: =SUMIF(Pivot!$A$45:$H$84,B13,Pivot!$H$45:$H$84)/118% | K13: =SUM(D13:J13)
D14: =SUMIF(Pivot!$A$45:$A$84,B14,Pivot!$B$45:$B$84)/118% | E14: =SUMIF(Pivot!$A$45:$A$84,B14,Pivot!$C$45:$C$84)/118% | F14: =SUMIF(Pivot!$A$45:$A$84,B14,Pivot!$D$45:$D$84)/118% | G14: =SUMIF(Pivot!$A$45:$A$84,B14,Pivot!$E$45:$E$84)/118% | H14: =SUMIF(Pivot!$A$45:$A$84,B14,Pivot!$F$45:$F$84)/118% | I14: =SUMIF(Pivot!$A$45:$A$84,B14,Pivot!$G$45:$G$84)/118% | J14: =SUMIF(Pivot!$A$45:$H$84,B14,Pivot!$H$45:$H$84)/118% | K14: =SUM(D14:J14)
B15: Other Than Annual Subscriptions | D15: =SUMIF(Pivot!$A$45:$A$84,B15,Pivot!$B$45:$B$84)/118% | E15: =SUMIF(Pivot!$A$45:$A$84,B15,Pivot!$C$45:$C$84)/118% | F15: =SUMIF(Pivot!$A$45:$A$84,B15,Pivot!$D$45:$D$84)/118% | G15: =SUMIF(Pivot!$A$45:$A$84,B15,Pivot!$E$45:$E$84)/118% | H15: =SUMIF(Pivot!$A$45:$A$84,B15,Pivot!$F$45:$F$84)/118% | I15: =SUMIF(Pivot!$A$45:$A$84,B15,Pivot!$G$45:$G$84)/118% | J15: =SUMIF(Pivot!$A$45:$H$84,B15,Pivot!$H$45:$H$84)/118% | K15: =SUM(D15:J15)
B16: 10 -Days -Upfront | D16: =SUMIF(Pivot!$A$45:$A$84,B16,Pivot!$B$45:$B$84)/118% | E16: =SUMIF(Pivot!$A$45:$A$84,B16,Pivot!$C$45:$C$84)/118% | F16: =SUMIF(Pivot!$A$45:$A$84,B16,Pivot!$D$45:$D$84)/118% | G16: =SUMIF(Pivot!$A$45:$A$84,B16,Pivot!$E$45:$E$84)/118% | H16: =SUMIF(Pivot!$A$45:$A$84,B16,Pivot!$F$45:$F$84)/118% | I16: =SUMIF(Pivot!$A$45:$A$84,B16,Pivot!$G$45:$G$84)/118% | J16: =SUMIF(Pivot!$A$45:$H$84,B16,Pivot!$H$45:$H$84)/118% | K16: =SUM(D16:J16)
B17: 12 -Days -Upfront | D17: =SUMIF(Pivot!$A$45:$A$84,B17,Pivot!$B$45:$B$84)/118% | E17: =SUMIF(Pivot!$A$45:$A$84,B17,Pivot!$C$45:$C$84)/118% | F17: =SUMIF(Pivot!$A$45:$A$84,B17,Pivot!$D$45:$D$84)/118% | G17: =SUMIF(Pivot!$A$45:$A$84,B17,Pivot!$E$45:$E$84)/118% | H17: =SUMIF(Pivot!$A$45:$A$84,B17,Pivot!$F$45:$F$84)/118% | I17: =SUMIF(Pivot!$A$45:$A$84,B17,Pivot!$G$45:$G$84)/118% | J17: =SUMIF(Pivot!$A$45:$H$84,B17,Pivot!$H$45:$H$84)/118% | K17: =SUM(D17:J17)
B18: 15 -Days -Upfront | D18: =SUMIF(Pivot!$A$45:$A$84,B18,Pivot!$B$45:$B$84)/118% | E18: =SUMIF(Pivot!$A$45:$A$84,B18,Pivot!$C$45:$C$84)/118% | F18: =SUMIF(Pivot!$A$45:$A$84,B18,Pivot!$D$45:$D$84)/118% | G18: =SUMIF(Pivot!$A$45:$A$84,B18,Pivot!$E$45:$E$84)/118% | H18: =SUMIF(Pivot!$A$45:$A$84,B18,Pivot!$F$45:$F$84)/118% | I18: =SUMIF(Pivot!$A$45:$A$84,B18,Pivot!$G$45:$G$84)/118% | J18: =SUMIF(Pivot!$A$45:$H$84,B18,Pivot!$H$45:$H$84)/118% | K18: =SUM(D18:J18)
B19: 13 month-Upfront | D19: =SUMIF(Pivot!$A$45:$A$84,B19,Pivot!$B$45:$B$84)/118% | E19: =SUMIF(Pivot!$A$45:$A$84,B19,Pivot!$C$45:$C$84)/118% | F19: =SUMIF(Pivot!$A$45:$A$84,B19,Pivot!$D$45:$D$84)/118% | G19: =SUMIF(Pivot!$A$45:$A$84,B19,Pivot!$E$45:$E$84)/118% | H19: =SUMIF(Pivot!$A$45:$A$84,B19,Pivot!$F$45:$F$84)/118% | I19: =SUMIF(Pivot!$A$45:$A$84,B19,Pivot!$G$45:$G$84)/118% | J19: =SUMIF(Pivot!$A$45:$H$84,B19,Pivot!$H$45:$H$84)/118% | K19: =SUM(D19:J19)
B20: 19 -Days -Upfront | D20: =SUMIF(Pivot!$A$45:$A$84,B20,Pivot!$B$45:$B$84)/118% | E20: =SUMIF(Pivot!$A$45:$A$84,B20,Pivot!$C$45:$C$84)/118% | F20: =SUMIF(Pivot!$A$45:$A$84,B20,Pivot!$D$45:$D$84)/118% | G20: =SUMIF(Pivot!$A$45:$A$84,B20,Pivot!$E$45:$E$84)/118% | H20: =SUMIF(Pivot!$A$45:$A$84,B20,Pivot!$F$45:$F$84)/118% | I20: =SUMIF(Pivot!$A$45:$A$84,B20,Pivot!$G$45:$G$84)/118% | J20: =SUMIF(Pivot!$A$45:$H$84,B20,Pivot!$H$45:$H$84)/118% | K20: =SUM(D20:J20)
B21: 38 -Days -Upfront | D21: =SUMIF(Pivot!$A$45:$A$84,B21,Pivot!$B$45:$B$84)/118% | E21: =SUMIF(Pivot!$A$45:$A$84,B21,Pivot!$C$45:$C$84)/118% | F21: =SUMIF(Pivot!$A$45:$A$84,B21,Pivot!$D$45:$D$84)/118% | G21: =SUMIF(Pivot!$A$45:$A$84,B21,Pivot!$E$45:$E$84)/118% | H21: =SUMIF(Pivot!$A$45:$A$84,B21,Pivot!$F$45:$F$84)/118% | I21: =SUMIF(Pivot!$A$45:$A$84,B21,Pivot!$G$45:$G$84)/118% | J21: =SUMIF(Pivot!$A$45:$H$84,B21,Pivot!$H$45:$H$84)/118% | K21: =SUM(D21:J21)
B22: 1 month-Upfront | D22: =SUMIF(Pivot!$A$45:$A$84,B22,Pivot!$B$45:$B$84)/118% | E22: =SUMIF(Pivot!$A$45:$A$84,B22,Pivot!$C$45:$C$84)/118% | F22: =SUMIF(Pivot!$A$45:$A$84,B22,Pivot!$D$45:$D$84)/118% | G22: =SUMIF(Pivot!$A$45:$A$84,B22,Pivot!$E$45:$E$84)/118% | H22: =SUMIF(Pivot!$A$45:$A$84,B22,Pivot!$F$45:$F$84)/118% | I22: =SUMIF(Pivot!$A$45:$A$84,B22,Pivot!$G$45:$G$84)/118% | J22: =SUMIF(Pivot!$A$45:$H$84,B22,Pivot!$H$45:$H$84)/118% | K22: =SUM(D22:J22)
B23: 2 months subscription, Monthly | D23: =SUMIF(Pivot!$A$45:$A$84,B23,Pivot!$B$45:$B$84)/118% | E23: =SUMIF(Pivot!$A$45:$A$84,B23,Pivot!$C$45:$C$84)/118% | F23: =SUMIF(Pivot!$A$45:$A$84,B23,Pivot!$D$45:$D$84)/118% | G23: =SUMIF(Pivot!$A$45:$A$84,B23,Pivot!$E$45:$E$84)/118% | H23: =SUMIF(Pivot!$A$45:$A$84,B23,Pivot!$F$45:$F$84)/118% | I23: =SUMIF(Pivot!$A$45:$A$84,B23,Pivot!$G$45:$G$84)/118% | J23: =SUMIF(Pivot!$A$45:$H$84,B23,Pivot!$H$45:$H$84)/118% | K23: =SUM(D23:J23)
B24: 2 months- Upfront | D24: =SUMIF(Pivot!$A$45:$A$84,B24,Pivot!$B$45:$B$84)/118% | E24: =SUMIF(Pivot!$A$45:$A$84,B24,Pivot!$C$45:$C$84)/118% | F24: =SUMIF(Pivot!$A$45:$A$84,B24,Pivot!$D$45:$D$84)/118% | G24: =SUMIF(Pivot!$A$45:$A$84,B24,Pivot!$E$45:$E$84)/118% | H24: =SUMIF(Pivot!$A$45:$A$84,B24,Pivot!$F$45:$F$84)/118% | I24: =SUMIF(Pivot!$A$45:$A$84,B24,Pivot!$G$45:$G$84)/118% | J24: =SUMIF(Pivot!$A$45:$H$84,B24,Pivot!$H$45:$H$84)/118% | K24: =SUM(D24:J24)
B25: 2 month & 13 Days-Upfront | D25: =SUMIF(Pivot!$A$45:$A$84,B25,Pivot!$B$45:$B$84)/118% | E25: =SUMIF(Pivot!$A$45:$A$84,B25,Pivot!$C$45:$C$84)/118% | F25: =SUMIF(Pivot!$A$45:$A$84,B25,Pivot!$D$45:$D$84)/118% | G25: =SUMIF(Pivot!$A$45:$A$84,B25,Pivot!$E$45:$E$84)/118% | H25: =SUMIF(Pivot!$A$45:$A$84,B25,Pivot!$F$45:$F$84)/118% | I25: =SUMIF(Pivot!$A$45:$A$84,B25,Pivot!$G$45:$G$84)/118% | J25: =SUMIF(Pivot!$A$45:$H$84,B25,Pivot!$H$45:$H$84)/118% | K25: =SUM(D25:J25)
B26: 3 months subscription, Monthly | D26: =SUMIF(Pivot!$A$45:$A$84,B26,Pivot!$B$45:$B$84)/118% | E26: =SUMIF(Pivot!$A$45:$A$84,B26,Pivot!$C$45:$C$84)/118% | F26: =SUMIF(Pivot!$A$45:$A$84,B26,Pivot!$D$45:$D$84)/118% | G26: =SUMIF(Pivot!$A$45:$A$84,B26,Pivot!$E$45:$E$84)/118% | H26: =SUMIF(Pivot!$A$45:$A$84,B26,Pivot!$F$45:$F$84)/118% | I26: =SUMIF(Pivot!$A$45:$A$84,B26,Pivot!$G$45:$G$84)/118% | J26: =SUMIF(Pivot!$A$45:$H$84,B26,Pivot!$H$45:$H$84)/118% | K26: =SUM(D26:J26)
... B45: 1year & 6 months - Half Yearly Payment | D45: =SUMIF(Pivot!$A$45:$A$84,B45,Pivot!$B$45:$B$84)/118% | E45: =SUMIF(Pivot!$A$45:$A$84,B45,Pivot!$C$45:$C$84)/118% | F45: =SUMIF(Pivot!$A$45:$A$84,B45,Pivot!$D$45:$D$84)/118% | G45: =SUMIF(Pivot!$A$45:$A$84,B45,Pivot!$E$45:$E$84)/118% | H45: =SUMIF(Pivot!$A$45:$A$84,B45,Pivot!$F$45:$F$84)/118% | I45: =SUMIF(Pivot!$A$45:$A$84,B45,Pivot!$G$45:$G$84)/118% | J45: =SUMIF(Pivot!$A$45:$H$84,B45,Pivot!$H$45:$H$84)/118% | K45: =SUM(D45:J45)
B47: Monthly Revenue from B2C subscribers (B) | D47: ='MR-AR'!C48 | E47: ='MR-AR'!D48 | F47: ='MR-AR'!E48 | G47: =Invoices!M16 | H47: =Invoices!M17 | I47: =Invoices!M18 | J47: =Invoices!M20 | K47: =SUM(D47:J47)
B49: Monthly Revenue from B2B and B2C C=A+B | D49: =D6+D47 | E49: =E6+E47 | F49: =F6+F47 | G49: =G6+G47 | H49: =H6+H47 | I49: =I6+I47 | J49: =J6+J47 | K49: =SUM(D49:J49)

Sheet FY 25-26-Accrual
A1: Coresphere100 Technologies Pvt. Ltd. | F1: Contracts expiring within | G1: 30 | H1: 45777 | I1: 45748 | N1: 45778 | O1: 45808 | R1: 45809 | W1: 45870
A2: Invoices Details | I2: =SUBTOTAL(9,I4:I1944) | J2: =SUBTOTAL(9,J4:J1944) | K2: =SUBTOTAL(9,K4:K1944) | N2: =SUBTOTAL(9,N4:N1944) | P2: =SUBTOTAL(9,P4:P1944) | Q2: =SUBTOTAL(9,Q4:Q1944) | R2: 45838 | S2: =SUBTOTAL(9,S4:S1944) | T2: =SUBTOTAL(9,T4:T1944) | U2: 45869 | V2: =SUBTOTAL(9,V4:V1944) | W2: 45900 | X2: =SUBTOTAL(9,X4:X1944) | Y2: =SUBTOTAL(9,Y4:Y1944) | Z2: 45930 | AA2: =SUBTOTAL(9,AA4:AA1944) | AB2: =SUBTOTAL(9,AB4:AB1944) | AC2: 45961 | AD2: =SUBTOTAL(9,AD4:AD1944) | AE2: =SUBTOTAL(9,AE4:AE1944)
A3: Contract | B3: Months | C3: Customer Name | D3: Invoice Number | E3: Nature of service | F3: Start Date | G3: End Date | H3: Payment Cycle | I3: Contract Amount | J3: Invoiced amount for April | K3: Invoiced amount for MAY | L3: Contract period | M3: Days in April | N3: April Sales (Days Wise) | O3: Days in May | P3: May Sales (Days Wise) | Q3: June in months | R3: Days in June | S3: June in days | T3: July in months | U3: Days in July | V3: July in days | W3: Days in Aug | X3: Aug Sales in months | Y3: Aug Sales in days | Z3: Days in Sept | AA3: Sept Sales in months | AB3: Sept Sales in days | AC3: Days in Oct | AD3: Oct Sales in months | AE3: Oct Sales in days
A4: 0 | B4: 45748 | C4: Touchstone Partners | D4: INV-25-26-000001, INV-25-26-000507 | E4: subscription based service | F4: 45748 | G4: 45838 | H4: 3 months subscription, upfront | I4: 70800 | J4: 23600 | K4: 23600 | L4: 91 | M4: 30 | N4: 23340.659 | O4: 31 | P4: 24118.681 | Q4: 23600 | R4: 30 | S4: 23340.659 | U4: 31 | W4: 0 | X4: 0 | Y4: 0
A5: Closed- May 25 | B5: 45748 | C5: Bimal Rajasekhar | D5: INV-25-26-000002 | E5: subscription based service | F5: 45748 | G5: 45808 | H5: 2 months- Upfront | I5: 35400 | J5: 17700 | K5: 17700 | L5: 61 | M5: 30 | N5: 17409.836 | O5: 31 | P5: 17990.164 | R5: 30 | U5: 31 | W5: 0 | X5: 0 | Y5: 0
A6: 0 | B6: 45748 | C6: Veritas Legal Advocates and Solicitors | D6: INV-25-26-000003, INV-25-26-000534 | E6: subscription based service | F6: 45749 | G6: 45932 | H6: 6 month-Upfront | I6: 1172448 | J6: 195408 | K6: 195408 | L6: 184 | M6: 29 | N6: 184788 | O6: 31 | P6: 197532 | Q6: 195408 | R6: 30 | S6: 191160 | T6: 195408 | U6: 31 | V6: 197532 | W6: 31 | X6: 195408 | Y6: 197532 | Z6: 30 | AA6: 195408 | AB6: 191160 | AC6: 2 | AD6: 167492.57 | AE6: 12744
A7: 0 | B7: Apr & May 25 | C7: LEGALOGIC CONSULTING LLP | D7: INV-25-26-000004, 104, INV-25-26-000490 | E7: subscription based service | F7: 45748 | G7: 45808 | H7: 2 months subscription, Monthly | I7: 70800 | J7: 35400 | K7: 35400 | L7: 61 | M7: 30 | N7: 34819.672 | O7: 31 | P7: 35980.328 | R7: 30 | U7: 31 | W7: 0 | X7: 0 | Y7: 0
A8: 0 | B8: 45748 | C8: VACUITAS COUNSELLOR LLP | D8: INV-25-26-000005 | E8: subscription based service | F8: 45750 | G8: 46114 | H8: Annual Upfront | I8: 116820 | J8: 9735 | K8: 9735 | L8: 365 | M8: 28 | N8: 8961.534 | O8: 31 | P8: 9921.699 | Q8: 9735 | R8: 30 | S8: 9601.6438 | T8: 9735 | U8: 31 | V8: 9921.6986 | W8: 31 | X8: 9735 | Y8: 9921.699 | Z8: 30 | AA8: 9735 | AB8: 9601.644 | AC8: 31 | AD8: 9735 | AE8: 9921.699
A9: Closed-Apr 25 | B9: 45748 | C9: Tvashta Law | D9: INV-25-26-000006 | E9: One time work | F9: 45748 | G9: 45777 | H9: 1 month-Upfront | I9: 2360 | J9: 2360 | L9: 30 | M9: 30 | N9: 2360 | O9: 0 | P9: 0 | R9: 30 | U9: 31 | W9: 0 | X9: 0 | Y9: 0
A10: 0 | B10: 45748 | C10: U. S. GANDHI & CO. | D10: INV-25-26-000007 | E10: subscription based service | F10: 45754 | G10: 45814 | H10: 2 months- Upfront | I10: 9440 | J10: 4720 | K10: 4720 | L10: 61 | M10: 24 | N10: 3714.098 | O10: 31 | P10: 4797.377 | R10: 6 | S10: 928.52459 | U10: 31 | W10: 0 | X10: 0 | Y10: 0
A11: Credit Note Issue | B11: 45748 | C11: Advocate Rohit Jaiswal | D11: INV-25-26-000009,00107,00177 | E11: subscription based service | F11: 45762 | G11: 45791 | H11: 1 month-Upfront | I11: 5900 | J11: 5900 | K11: 0 | L11: 30 | M11: 16 | N11: 3146.667 | O11: 14 | P11: 2753.333 | S11: 0 | V11: 0 | W11: 0 | X11: 0 | Y11: 0
A12: 0 | B12: 45748 | C12: Dileep Poolakkot | D12: INV-25-26-000010 | E12: subscription based service | F12: 45755 | G12: 46119 | H12: Annual Upfront | I12: 70800 | J12: 5900 | K12: 5900 | L12: 365 | M12: 23 | N12: 4461.37 | O12: 31 | P12: 6013.151 | Q12: 5900 | R12: 30 | S12: 5819.1781 | T12: 5900 | U12: 31 | V12: 6013.1507 | W12: 31 | X12: 5900 | Y12: 6013.151 | Z12: 30 | AA12: 5900 | AB12: 5819.178 | AC12: 31 | AD12: 5900 | AE12: 6013.151
A13: 0 | B13: 45748 | C13: Utkarsh Joshi | D13: INV-25-26-000011 | E13: subscription based service | F13: 45755 | G13: 45815 | H13: 2 months- Upfront | I13: 7080 | J13: 3540 | K13: 3540 | L13: 61 | M13: 23 | N13: 2669.508 | O13: 31 | P13: 3598.033 | R13: 7 | S13: 812.45902 | U13: 31 | W13: 0 | X13: 0 | Y13: 0
A14: 0 | B14: 45748 | C14: Karan Butalia | D14: INV-25-26-000012 | E14: subscription based service | F14: 45755 | G14: 45815 | H14: 2 months- Upfront | I14: 4720 | J14: 2360 | K14: 2360 | L14: 61 | M14: 23 | N14: 1779.672 | O14: 31 | P14: 2398.689 | R14: 7 | S14: 541.63934 | U14: 31 | W14: 0 | X14: 0 | Y14: 0
A15: 0 | B15: Jan & Apr & July & Oct 25 | C15: Agama Law Associates | D15: INV- 46, INV-25-26-000013, 277, 483, INV-25-26- (46-jan), 000013, 000277, 000483 | E15: subscription based service | F15: 45658 | G15: 46022 | H15: Annual subscription, Quarterly upfront | I15: 320000 | J15: 26666.667 | K15: 26666.667 | L15: 365 | M15: 30 | N15: 26301.37 | O15: 31 | P15: 27178.082 | Q15: 26666.667 | R15: 30 | S15: 26301.37 | T15: 26666.667 | U15: 31 | V15: 27178.082 | W15: 31 | X15: 26666.667 | Y15: 27178.082 | Z15: 30 | AA15: 26666.667 | AB15: 26301.37 | AC15: 31 | AD15: 26666.667 | AE15: 27178.082
A16: Closed- May 25 | B16: 45748 | C16: RAJANI ASSOCIATES | D16: INV-25-26-000014 | E16: subscription based service | F16: 45757 | G16: 45786 | H16: 1 month-Upfront | I16: 24780 | J16: 24780 | L16: 30 | M16: 21 | N16: 17346 | O16: 9 | P16: 7434 | R16: 30 | U16: 31 | W16: 0 | X16: 0 | Y16: 0
A17: 0 | B17: 45748 | C17: Venkatesh Dhond | D17: INV-25-26-000015 | E17: subscription based service | F17: 45716 | G17: 45896 | H17: 6 month-Upfront | I17: 100890 | J17: 16815 | K17: 16815 | L17: 181 | M17: 30 | N17: 16722.099 | O17: 31 | P17: 17279.503 | Q17: 16815 | R17: 30 | S17: 16722.099 | T17: 16815 | U17: 31 | V17: 17279.503 | W17: 27 | X17: 0 | Y17: 15049.89
A18: 0 | B18: Mar to June 25 | C18: Harshit Malik | D18: INV-000111, INV-25-26-000016, 0109 | E18: subscription based service | F18: 45725 | G18: 45786 | H18: 2 months subscription, Monthly | I18: 23600 | J18: 11800 | L18: 62 | M18: 30 | N18: 11419.355 | O18: 9 | P18: 3425.806 | R18: 30 | U18: 31 | W18: 0 | X18: 0 | Y18: 0
A19: 0 | B19: 45748 | C19: PSN Legal Advocates and Legal Consultants | D19: INV-25-26-000017 | E19: subscription based service | F19: 45757 | G19: 46121 | H19: Annual Upfront | I19: 177015 | J19: 14751.25 | K19: 14751.25 | L19: 365 | M19: 21 | N19: 10184.425 | O19: 31 | P19: 15034.151 | Q19: 14751.25 | R19: 30 | S19: 14549.178 | T19: 14751.25 | U19: 31 | V19: 15034.151 | W19: 31 | X19: 14751.25 | Y19: 15034.151 | Z19: 30 | AA19: 14751.25 | AB19: 14549.178 | AC19: 31 | AD19: 14751.25 | AE19: 15034.151
A20: 0 | B20: Apr to July 25 | C20: Swapna Sheshadri | D20: INV-25-26-000019, 113, 0184, 259, INV-25-26-000304, 000376, 000459, 000551, 000673 | E20: subscription based service | F20: 45757 | G20: 45878 | H20: 4 months subscription, Monthly | I20: 47200 | J20: 11800 | K20: 11800 | L20: 122 | M20: 21 | N20: 8124.59 | O20: 31 | P20: 11993.443 | Q20: 11800 | R20: 30 | S20: 11606.557 | T20: 11800 | U20: 31 | V20: 11993.443 | W20: 9 | Y20: 3481.967
A21: 0 | B21: 45748 | C21: Vutts & Associates LLP | D21: INV-25-26-000020 | E21: subscription based service | F21: 45758 | G21: 45848 | H21: 3 months subscription, upfront | I21: 35400 | J21: 11800 | K21: 11800 | L21: 91 | M21: 20 | N21: 7780.22 | O21: 31 | P21: 12059.341 | Q21: 11800 | R21: 30 | S21: 11670.33 | U21: 10 | V21: 3890.1099 | W21: 0 | X21: 0 | Y21: 0
A22: 0 | B22: Feb Apr to Oct 25 | C22: Darius J. Khambata | D22: INV-000085, INV-25-26-000021, INV-25-26-000022, 148, 178, 248, 337, 416, 500, 000178, 000248, 000022, 000148, 000337, 000416, 000500, 000600 | E22: subscription based service | F22: 45695 | G22: 46059 | H22: Annual-Monthly | I22: 240000 | J22: 20000 | K22: 20000 | L22: 365 | M22: 30 | N22: 19726.027 | O22: 31 | P22: 20383.562 | Q22: 20000 | R22: 30 | S22: 19726.027 | T22: 20000 | U22: 31 | V22: 20383.562 | W22: 31 | X22: 20000 | Y22: 20383.562 | Z22: 30 | AA22: 20000 | AB22: 19726.027 | AC22: 31 | AD22: 20000 | AE22: 20383.562
A23: 0 | B23: 45748 | C23: Miglani Varma & Co. | D23: INV-25-26-000023 | E23: subscription based service | F23: 45758 | G23: 45848 | H23: 3 months subscription, upfront | I23: 17700 | J23: 5900 | K23: 5900 | L23: 91 | M23: 20 | N23: 3890.11 | O23: 31 | P23: 6029.67 | Q23: 5900 | R23: 30 | S23: 5835.1648 | U23: 10 | V23: 1945.0549 | W23: 0 | X23: 0 | Y23: 0
A24: Closed- May 25 | B24: 45748 | C24: Venkatesh Mohanraj | D24: INV-25-26-000024 | E24: subscription based service | F24: 45759 | G24: 45788 | H24: 1 month-Upfront | I24: 5900 | J24: 5900 | L24: 30 | M24: 19 | N24: 3736.667 | O24: 11 | P24: 2163.333 | R24: 30 | U24: 31 | W24: 0 | X24: 0 | Y24: 0
A25: Closed- May 25 | B25: 45748 | C25: Jade Lex Partners | D25: INV-25-26-000025 | E25: subscription based service | F25: 45759 | G25: 45788 | H25: 1 month-Upfront | I25: 7080 | J25: 7080 | L25: 30 | M25: 19 | N25: 4484 | O25: 11 | P25: 2596 | R25: 30 | U25: 31 | W25: 0 | X25: 0 | Y25: 0
A26: Closed- May 25 | B26: 45748 | C26: Alankrit Bajpai | D26: INV-25-26-000026 | E26: subscription based service | F26: 45759 | G26: 45788 | H26: 1 month-Upfront | I26: 5900 | J26: 5900 | L26: 30 | M26: 19 | N26: 3736.667 | O26: 11 | P26: 2163.333 | R26: 30 | U26: 31 | W26: 0 | X26: 0 | Y26: 0
A27: Closed- May 25 | B27: 45748 | C27: Badar Durrez | D27: INV-25-26-000028 | E27: subscription based service | F27: 45760 | G27: 45789 | H27: 1 month-Upfront | I27: 5900 | J27: 5900 | L27: 30 | M27: 18 | N27: 3540 | O27: 12 | P27: 2360 | R27: 30 | U27: 31 | W27: 0 | X27: 0 | Y27: 0
A28: 0 | B28: 45748 | C28: Rashmikant and Partners | D28: INV-25-26-000029 | E28: subscription based service | F28: 45761 | G28: 46125 | H28: Annual Upfront | I28: 259600 | J28: 21633.333 | K28: 21633.333 | L28: 365 | M28: 17 | N28: 12090.959 | O28: 31 | P28: 22048.219 | Q28: 21633.333 | R28: 30 | S28: 21336.986 | T28: 21633.333 | U28: 31 | V28: 22048.219 | W28: 31 | X28: 21633.333 | Y28: 22048.219 | Z28: 30 | AA28: 21633.333 | AB28: 21336.986 | AC28: 31 | AD28: 21633.333 | AE28: 22048.219
A29: 0 | B29: Apr to June 25 | C29: TLH, Advocates & Solicitors | D29: INV-25-26-000030, 124, 198,271 | E29: subscription based service | F29: 45762 | G29: 45852 | H29: 3 months subscription, Monthly | I29: 531000 | J29: 177000 | K29: 177000 | L29: 91 | M29: 16 | N29: 93362.637 | O29: 31 | P29: 180890.11 | Q29: 177000 | R29: 30 | S29: 175054.95 | U29: 14 | V29: 81692.308 | W29: 0 | X29: 0 | Y29: 0
A30: 0 | B30: 45748 | C30: Shreeyash Lalit | D30: INV-25-26-000032 | E30: subscription based service | F30: 45762 | G30: 45944 | H30: 6 month-Upfront | I30: 42480 | J30: 7080 | K30: 7080 | L30: 183 | M30: 16 | N30: 3714.098 | O30: 31 | P30: 7196.066 | Q30: 7080 | R30: 30 | S30: 6963.9344 | T30: 7080 | U30: 31 | V30: 7196.0656 | W30: 31 | X30: 7080 | Y30: 7196.066 | Z30: 30 | AA30: 7080 | AB30: 6963.934 | AC30: 14 | AD30: 7080 | AE30: 3249.836
A31: 0 | B31: 45748 | C31: Dewani Associates | D31: INV-25-26-000033 | E31: subscription based service | F31: 45762 | G31: 45823 | H31: 2 months- Upfront | I31: 23600 | J31: 11800 | K31: 11800 | L31: 62 | M31: 16 | N31: 6090.323 | O31: 31 | P31: 11800 | R31: 15 | S31: 5709.6774 | U31: 31 | W31: 0 | X31: 0 | Y31: 0
A32: 0 | B32: Apr to Oct 25 | C32: R. Vishnu Kumar, Advocate | D32: INV-25-26-000034, 125, 199, 272, 358, 528, INV-25-26-000034-000125, 000199, 000272, 000358, 000432, 000528, 000631 | E32: subscription based service | F32: 45762 | G32: 46126 | H32: Annual-Monthly | I32: 240000 | J32: 20000 | K32: 20000 | L32: 365 | M32: 16 | N32: 10520.548 | O32: 31 | P32: 20383.562 | Q32: 20000 | R32: 30 | S32: 19726.027 | T32: 20000 | U32: 31 | V32: 20383.562 | W32: 31 | X32: 20000 | Y32: 20383.562 | Z32: 30 | AA32: 20000 | AB32: 19726.027 | AC32: 31 | AD32: 20000 | AE32: 20383.562
A33: 0 | B33: Mar & Apr 25 | C33: Yash Momaya | D33: INV-25-26-000035, 0127, 0200 | E33: subscription based service | F33: 45763 | G33: 45792 | H33: 1 month-Upfront | I33: 11800 | J33: 11800 | L33: 30 | M33: 15 | N33: 5900 | O33: 15 | P33: 5900 | Q33: 0 | R33: 30 | S33: 0 | T33: 0 | U33: 31 | V33: 0 | W33: 0 | X33: 0 | Y33: 0
A34: Closed- May 25 | B34: 45748 | C34: Chetan Dedhia | D34: INV-25-26-000036 | E34: subscription based service | F34: 45763 | G34: 45792 | H34: 1 month-Upfront | I34: 17700 | J34: 17700 | L34: 30 | M34: 15 | N34: 8850 | O34: 15 | P34: 8850 | R34: 30 | U34: 31 | W34: 0 | X34: 0 | Y34: 0
A35: 0 | B35: 45748 | C35: NC Legal | D35: INV-25-26-000037 | E35: subscription based service | F35: 45778 | G35: 46142 | H35: Annual Upfront | I35: 80240 | K35: 6686.667 | L35: 365 | M35: 0 | N35: 0 | O35: 31 | P35: 6814.904 | Q35: 6686.6667 | R35: 30 | S35: 6595.0685 | T35: 6686.6667 | U35: 31 | V35: 6814.9041 | W35: 31 | X35: 6686.667 | Y35: 6814.904 | Z35: 30 | AA35: 6686.667 | AB35: 6595.068 | AC35: 31 | AD35: 6686.667 | AE35: 6814.904
A36: Closed- May 25 | B36: 45748 | C36: Aakash Sharma | D36: INV-25-26-000038 | E36: subscription based service | F36: 45765 | G36: 45795 | H36: 1 month-Upfront | I36: 5900 | J36: 5900 | L36: 31 | M36: 13 | N36: 2474.194 | O36: 18 | P36: 3425.806 | R36: 30 | U36: 31 | W36: 0 | X36: 0 | Y36: 0
A37: Closed- May 25 | B37: 45748 | C37: Saga Legal | D37: INV-25-26-000039 | E37: subscription based service | F37: 45761 | G37: 45791 | H37: 1 month-Upfront | I37: 23600 | J37: 23600 | L37: 31 | M37: 17 | N37: 12941.935 | O37: 14 | P37: 10658.065 | R37: 30 | U37: 31 | W37: 0 | X37: 0 | Y37: 0
A38: 0 | B38: 45748 | C38: RPV LEGAL | D38: INV-25-26-000040 | E38: subscription based service | F38: 45769 | G38: 46133 | H38: Annual Upfront | I38: 175000 | J38: 14583.333 | K38: 14583.333 | L38: 365 | M38: 9 | N38: 4315.068 | O38: 31 | P38: 14863.014 | Q38: 14583.333 | R38: 30 | S38: 14383.562 | T38: 14583.333 | U38: 31 | V38: 14863.014 | W38: 31 | X38: 14583.333 | Y38: 14863.014 | Z38: 30 | AA38: 14583.333 | AB38: 14383.562 | AC38: 31 | AD38: 14583.333 | AE38: 14863.014
A39: 0 | B39: 45748 | C39: AP & Partners, Advocates | D39: INV-25-26-000041 | E39: subscription based service | F39: 45771 | G39: 45860 | H39: 3 months subscription, upfront | I39: 28320 | J39: 9440 | K39: 9440 | L39: 90 | M39: 7 | N39: 2202.667 | O39: 31 | P39: 9754.667 | Q39: 9440 | R39: 30 | S39: 9440 | U39: 22 | V39: 6922.6667 | W39: 0 | X39: 0 | Y39: 0
A40: Credit Note Issue | B40: Apr to June 25 | C40: Pranay Chitale | D40: INV-25-26-000042, 137, 213 | E40: subscription based service | F40: 45770 | G40: 45799 | H40: 1 month-Upfront | I40: 17700 | J40: 17700 | L40: 30 | M40: 8 | N40: 4720 | O40: 22 | P40: 12980 | W40: 0 | X40: 0 | Y40: 0
...

Sheet Invoices
F2: =SUBTOTAL(9,F23:F54) | H2: =SUBTOTAL(9,H23:H54)
A3: Months | B3: Invoice Date | C3: Invoice Number | D3: Invoice Status | E3: Customer Name | F3: Taxable Value | G3: Total Tax | H3: Total | I3: Nature
A4: 45627 | B4: 45628 | C4: INV-000027 | D4: Closed | E4: B2C | F4: 1295 | G4: 0 | H4: 1295 | I4: B2C | K4: Sum of Taxable Value | L4: Nature
A5: 45627 | B5: 45628 | C5: INV-000028 | D5: Closed | E5: Office of ASG (N. Venkatraman) | F5: 195000 | G5: 0 | H5: 195000 | I5: B2B | K5: Months | L5: B2B | M5: B2C | N5: (empty) | O5: Total Result
A6: 45627 | B6: 45635 | C6: INV-000029 | D6: Closed | E6: B2C | F6: 9164 | G6: 0 | H6: 9164 | I6: B2C | K6: 45536 | L6: 3999 | M6: 23809 | O6: 27808
A7: 45627 | B7: 45635 | C7: INV-000030 | D7: Closed | E7: Kanungo & Co. | F7: 3999 | G7: 0 | H7: 3999 | I7: B2B | K7: 45566 | L7: 49997 | M7: 41135 | O7: 91132
A8: 45627 | B8: 45638 | C8: INV-000031 | D8: Closed | E8: B2C | F8: 3786 | G8: 0 | H8: 3786 | I8: B2C | K8: 45597 | L8: 158496 | M8: 20926 | O8: 179422
A9: 45627 | B9: 45638 | C9: INV-000032 | D9: Closed | E9: Diwan Law Associates | F9: 5000 | G9: 0 | H9: 5000 | I9: B2B | K9: 45627 | L9: 514892 | M9: 34284 | O9: 549176
A10: 45627 | B10: 45639 | C10: INV-000033 | D10: Closed | E10: Aditya Sikka / Tvashta Law | F10: 45000 | G10: 0 | H10: 45000 | I10: B2B | K10: 45658 | L10: 1464041 | M10: 32266 | O10: 1496307
A11: 45627 | B11: 45639 | C11: INV-000034 | D11: Closed | E11: B2C | F11: 1493 | G11: 0 | H11: 1493 | I11: B2C | K11: 45689 | L11: 1192593 | M11: 33183 | O11: 1225776
A12: 45627 | B12: 45640 | C12: INV-000035 | D12: Closed | E12: Amrita Panda / Chambers of Amrita Panda | F12: 10000 | G12: 0 | H12: 10000 | I12: B2B | K12: 45717 | L12: 4569923 | M12: 50543 | O12: 4620466
A13: 45627 | B13: 45644 | C13: INV-000036 | D13: Closed | E13: B2C | F13: 5481 | G13: 0 | H13: 5481 | I13: B2C | K13: 45748 | L13: 4040388 | M13: 42252 | O13: 4082640
A14: 45627 | B14: 45644 | C14: INV-000037 | D14: Closed | E14: Ish Jain / Regius Partners LLP | F14: 146994 | G14: 0 | H14: 146994 | I14: B2B | K14: 45778 | L14: 4666763 | M14: 24128 | O14: 4690891
A15: 45627 | B15: 45645 | C15: INV-000038 | D15: Closed | E15: The Guild | Advocates & Associate Counsel | F15: 60000 | G15: 0 | H15: 60000 | I15: B2B | K15: 45809 | L15: 3054847.7 | M15: 24554.28 | O15: 3079401.9
A16: 45627 | B16: 45648 | C16: INV-000039 | D16: Closed | E16: B2C | F16: 2293 | G16: 0 | H16: 2293 | I16: B2C | K16: 45839 | L16: 8195261 | M16: 19474 | O16: 8214735
A17: 45627 | B17: 45648 | C17: INV-000040 | D17: Closed | E17: Manish kelker | F17: 3999 | G17: 0 | H17: 3999 | I17: B2B | K17: 45870 | L17: 9351621 | M17: 18627 | O17: 9370248
A18: 45627 | B18: 45651 | C18: INV-000041 | D18: Closed | E18: B2C | F18: 2095 | G18: 0 | H18: 2095 | I18: B2C | K18: 45901 | L18: 4189179.5 | M18: 14394.92 | O18: 4203574.5
A19: 45627 | B19: 45651 | C19: INV-000042 | D19: Closed | E19: Abhimanyu Garg / Methodica Legal | F19: 36900 | G19: 0 | H19: 36900 | I19: B2B | K19: (empty)
A20: 45627 | B20: 45655 | C20: INV-000043 | D20: Closed | E20: B2C | F20: 3687 | G20: 0 | H20: 3687 | I20: B2C | K20: 45931 | L20: 5730227.7 | M20: 13549.16 | O20: 5743776.8
A21: 45627 | B21: 45655 | C21: INV-000044 | D21: Closed | E21: SRCO Legal / Salvador Raghav & Co. | F21: 8000 | G21: 0 | H21: 8000 | I21: B2B | K21: Total Result | L21: 47182229 | M21: 393125.36 | O21: 47575354
A22: 45627 | B22: 45657 | C22: INV-000045 | D22: Closed | E22: B2C | F22: 4990 | G22: 0 | H22: 4990 | I22: B2C
A23: 45658 | B23: 45658 | C23: INV-000046 | D23: Closed | E23: Agama Law Associates | F23: 80000 | G23: 0 | H23: 80000 | I23: B2B
A24: 45658 | B24: 45662 | C24: INV-000047 | D24: Closed | E24: B2C | F24: 6780 | G24: 0 | H24: 6780 | I24: B2C
A25: 45658 | B25: 45662 | C25: INV-000048 | D25: Closed | E25: Gourab Banerji | F25: 49998 | G25: 0 | H25: 49998 | I25: B2B
A26: 45658 | B26: 45665 | C26: INV-000049 | D26: Closed | E26: B2C | F26: 1691 | G26: 0 | H26: 1691 | I26: B2C
A27: 45658 | B27: 45665 | C27: INV-000050 | D27: Closed | E27: Parakram Legal | F27: 5000 | G27: 0 | H27: 5000 | I27: B2B
A28: 45658 | B28: 45666 | C28: INV-000051 | D28: Closed | E28: Kanungo & Co. | F28: 3999 | G28: 0 | H28: 3999 | I28: B2B
A29: 45658 | B29: 45668 | C29: INV-000052 | D29: Closed | E29: B2C | F29: 4487 | G29: 0 | H29: 4487 | I29: B2C
A30: 45658 | B30: 45668 | C30: INV-000053 | D30: Closed | E30: Diwan Law Associates | F30: 5000 | G30: 0 | H30: 5000 | I30: B2B
A31: 45658 | B31: 45671 | C31: INV-000054 | D31: Closed | E31: B2C | F31: 1889 | G31: 0 | H31: 1889 | I31: B2C
A32: 45658 | B32: 45671 | C32: INV-000055 | D32: Closed | E32: Mustafa S. Doctor | F32: 162000 | G32: 0 | H32: 162000 | I32: B2B
A33: 45658 | B33: 45674 | C33: INV-000056 | D33: Closed | E33: B2C | F33: 5683 | G33: 0 | H33: 5683 | I33: B2C
... A308: 45597 | B308: 45626 | C308: INV-000026 | D308: Closed | E308: B2C | F308: 2293 | G308: 0 | H308: 2293 | I308: B2C
A309: 45809 | B309: 45809 | C309: INV-25-26-000161 | D309: Overdue | E309: LEGALOGIC CONSULTING LLP | F309: 38000 | G309: 6840 | H309: =F309+G309 | I309: B2B | J309: =VLOOKUP(C309,'FY 25-26-Accrual'!$D$192:$D$233,1,0)
A310: 45809 | B310: 45810 | C310: INV-25-26-000162 | D310: Closed | E310: B2C | F310: 6772.88 | G310: 1219.1184 | H310: =F310+G310 | I310: B2C | J310: =VLOOKUP(C310,'FY 25-26-Accrual'!$D$192:$D$233,1,0)
A311: 45809 | B311: 45810 | C311: INV-25-26-000163 | D311: Closed | E311: Poovayya & CO | F311: 20000 | G311: 3600 | H311: =F311+G311 | I311: B2B | J311: =VLOOKUP(C311,'FY 25-26-Accrual'!$D$192:$D$233,1,0)
A312: 45809 | B312: 45810 | C312: INV-25-26-000164 | D312: Closed | E312: Sajan Poovayya | F312: 20000 | G312: 3600 | H312: =F312+G312 | I312: B2B | J312: =VLOOKUP(C312,'FY 25-26-Accrual'!$D$192:$D$233,1,0)
A313: 45809 | B313: 45811 | C313: INV-25-26-000165 | D313: Overdue | E313: Shrey Lodha | F313: 10000 | G313: 1800 | H313: =F313+G313 | I313: B2B | J313: ='FY 25-26-Accrual'!$D$234
A314: 45809 | B314: 45812 | C314: INV-25-26-000166 | D314: Closed | E314: Gupta Law Associates | F314: 15000 | G314: 2700 | H314: =F314+G314 | I314: B2B | J314: =VLOOKUP(C314,'FY 25-26-Accrual'!$D$192:$D$233,1,0)
A315: 45809 | B315: 45812 | C315: INV-25-26-000167 | D315: Overdue | E315: Vardharma Chambers | F315: 7000 | G315: 1260 | H315: =F315+G315 | I315: B2B | J315: =VLOOKUP(C315,'FY 25-26-Accrual'!$D$192:$D$233,1,0)
...

Sheet Invoice
A1: Invoice Date | B1: Invoice ID | C1: Invoice Number | D1: Invoice Status | E1: Customer ID | F1: Customer Name | G1: Place of Supply | H1: Place of Supply(With State Code) | I1: GST Treatment | J1: Is Inclusive Tax | K1: Due Date | L1: PurchaseOrder | M1: Currency Code | N1: Exchange Rate | O1: Discount Type | P1: Is Discount Before Tax | Q1: Template Name | R1: Entity Discount Percent | S1: TCS Tax Name | T1: TCS Percentage | U1: TDS Calculation Type | V1: TDS Name | W1: TDS Percentage | X1: TDS Section Code | Y1: TDS Section | Z1: TDS Amount | AA1: SubTotal | AB1: Total | AC1: Balance | AD1: Adjustment | AE1: Adjustment Description | AF1: Expected Payment Date | AG1: Last Payment Date | AH1: Payment Terms | AI1: Payment Terms Label | AJ1: Notes | AK1: Terms & Conditions | AL1: E-WayBill Number | AM1: E-WayBill Generated Time | AN1: E-WayBill Status | AO1: E-WayBill Cancelled Time | AP1: E-WayBill Expired Time | AQ1: Transporter Name | AR1: Transporter ID | AS1: TCS Amount | AT1: Invoice Type | AU1: Entity Discount Amount | AV1: Shipping Charge | AW1: Shipping Charge Tax ID | AX1: Shipping Charge Tax Amount | AY1: Shipping Charge Tax Name | AZ1: Shipping Charge Tax % | BA1: Shipping Charge Tax Type | BB1: Shipping Charge Tax Exemption Code | BC1: Shipping Charge SAC Code | BD1: Item Name | BE1: Item Desc | BF1: Quantity | BG1: Discount | BH1: Discount Amount | BI1: Item Total | BJ1: Usage unit | BK1: Item Price | BL1: Product ID | BM1: Brand | BN1: Sales Order Number | BO1: Expense Reference ID | BP1: Recurrence Name | BQ1: Billing Attention | BR1: Billing Address | BS1: Billing Street2 | BT1: Billing City | BU1: Billing State | BV1: Billing Country | BW1: Billing Code | BX1: Billing Phone | BY1: Billing Fax | BZ1: Shipping Attention | CA1: Shipping Address | CB1: Shipping Street2 | CC1: Shipping City | CD1: Shipping State | CE1: Shipping Country | CF1: Shipping Code | CG1: Shipping Fax | CH1: Shipping Phone Number | CI1: Supplier Org Name | CJ1: Supplier GST Registration Number | CK1: Supplier Street Address | CL1: Supplier City | CM1: Supplier State | CN1: Supplier Country | CO1: Supplier ZipCode | CP1: Supplier Phone | CQ1: Supplier E-Mail | CR1: CGST Rate % | CS1: SGST Rate % | CT1: IGST Rate % | CU1: CESS Rate % | CV1: CGST(FCY) | CW1: SGST(FCY) | CX1: IGST(FCY) | CY1: CESS(FCY) | CZ1: CGST | DA1: SGST | DB1: IGST | DC1: CESS | DD1: Reverse Charge Tax Name | DE1: Reverse Charge Tax Rate | DF1: Reverse Charge Tax Type | DG1: Item TDS Name | DH1: Item TDS Percentage | DI1: Item TDS Amount | DJ1: Item TDS Section Code | DK1: Item TDS Section | DL1: GST Identification Number (GSTIN) | DM1: Nature Of Collection | DN1: Project ID | DO1: Project Name | DP1: HSN/SAC | DQ1: Round Off | DR1: Sales person | DS1: Subject | DT1: Primary Contact EmailID | DU1: Primary Contact Mobile | DV1: Primary Contact Phone | DW1: Estimate Number | DX1: Item Type | DY1: Custom Charges | DZ1: Shipping Bill# | EA1: Shipping Bill Date | EB1: Shipping Bill Total | EC1: PortCode | ED1: Reference Invoice# | EE1: Reference Invoice Date | EF1: Reference Invoice Type | EG1: GST Registration Number(Reference Invoice) | EH1: Reason for issuing Debit Note | EI1: E-Commerce Operator Name | EJ1: E-Commerce Operator GSTIN | EK1: Account | EL1: Account Code | EM1: Supply Type | EN1: Tax ID | EO1: Item Tax | EP1: Item Tax % | EQ1: Item Tax Amount | ER1: Item Tax Type | ES1: Item Tax Exemption Reason | ET1: Kit Combo Item Name
A2: 45748 | B2: 2297152000000050064 | C2: INV-25-26-000001 | D2: Closed | E2: 2297152000000050001 | F2: Touchstone Partners | G2: DL | H2: 07-Delhi | I2: business_none | J2: false | K2: 45748 | M2: INR | N2: 1 | O2: item_level | P2: true | Q2: Tax Invoice | R2: 0.00 | U2: entity_level | V2: Technical Fees (2%) | W2: 2.00 | X2: 194J | Y2: Section 194 J | Z2: 1200.000 | AA2: 60000 | AB2: =69600 | AC2: 0 | AD2: 0 | AE2: Adjustment | AG2: 45749 | AH2: 0 | AI2: Due On Receipt | AJ2: Thanks for your business. | AT2: Invoice | AU2: 0.0 | AV2: 0 | BD2: Jurisphere Enterprise Subscription | BE2: License Period- 1st Apr to 30th June25 Description- 10 licenses for 3 months, at Rs. 2000 each month per license | BF2: 3 | BG2: 0.00 | BH2: 0.00 | BI2: 60000 | BJ2: pcs | BK2: 20000 | BL2: 2297152000000039748 | BR2: 2nd Floor, Block E, The MIRA Plot 1 & 2, | BS2: Ishwar Nagar, Mathura Road, | BT2: New Delhi | BU2: Delhi | BV2: India | BW2: 110065 | CA2: 2nd Floor, Block E, The MIRA Plot 1 & 2, | CB2: Ishwar Nagar, Mathura Road, | CC2: New Delhi | CD2: Delhi | CE2: India | CF2: 110065 | CI2: Coresphere100 Technologies Pvt. Ltd. | CJ2: 09AALCC7037K1Z7 | CK2: 16026, 16th Floor, Tower Oakwood, | CL2: Greater Noida, | CM2: Uttar Pradesh | CN2: India | CO2: 201306 | CP2: 8928163657 | CQ2: manas@jurisphere.ai | CR2: 0.00 | CS2: 0.00 | CT2: 18.00 | CU2: 0.00 | CV2: 0.00 | CW2: 0.00 | CX2: 10800.00 | CY2: 0.00 | CZ2: 0.00 | DA2: 0.00 | DB2: 10800.00 | DC2: 0.00 | DP2: 998313 | DQ2: 0 | DX2: service | EH2: Others | EK2: Sales | EM2: Taxable | EN2: 2297152000000031111 | EO2: IGST18 | EP2: 18.00 | EQ2: 10800 | ER2: ItemAmount
A3: 45748 | B3: 2297152000000050138 | C3: INV-25-26-000002 | D3: Closed | E3: 2297152000000050113 | F3: Bimal Rajasekhar | G3: MH | H3: 27-Maharashtra | I3: business_none | J3: false | K3: 45748 | M3: INR | N3: 1 | O3: item_level | P3: true | Q3: Tax Invoice | R3: 0.00 | U3: item_level | W3: 0.00 | Z3: 0.000 | AA3: 30000 | AB3: 35400 | AC3: 0 | AD3: 0 | AE3: Adjustment | AG3: 45749 | AH3: 0 | AI3: Due On Receipt | AJ3: Thanks for your business. | AK3: 1. FLEXIBLE CANCELLATION, WITH PRO-RATED REFUND 2. ALL UPCOMING FEATURES WILL BE INCLUDED IN THE SUBSCRIPTION | AT3: Invoice | AU3: 0.0 | AV3: 0 | BD3: Jurisphere Enterprise Subscription | BE3: Period - 1st Apr 25 to 31st May 25 Description- Pilot Access of 5 licenses for 2 months of Rs.15000 per month | BF3: 2 | BG3: 0.00 | BH3: 0.00 | BI3: 30000 | BJ3: pcs | BK3: 15000 | BL3: 2297152000000039748 | CI3: Coresphere100 Technologies Pvt. Ltd. | CJ3: 09AALCC7037K1Z7 | CK3: 16026, 16th Floor, Tower Oakwood, | CL3: Greater Noida, | CM3: Uttar Pradesh | CN3: India | CO3: 201306 | CP3: 8928163657 | CQ3: manas@jurisphere.ai | CR3: 0.00 | CS3: 0.00 | CT3: 18.00 | CU3: 0.00 | CV3: 0.00 | CW3: 0.00 | CX3: 5400.00 | CY3: 0.00 | CZ3: 0.00 | DA3: 0.00 | DB3: 5400.00 | DC3: 0.00 | DI3: 0.000 | DP3: 998313 | DQ3: 0 | DX3: service | EH3: Others | EK3: Sales | EM3: Taxable | EN3: 2297152000000031111 | EO3: IGST18 | EP3: 18.00 | EQ3: 5400 | ER3: ItemAmount
A4: 45749 | B4: 2297152000000050202 | C4: INV-25-26-000003 | D4: Closed | E4: 2297152000000050184 | F4: Veritas Legal Advocates and Solicitors | G4: MH | H4: 27-Maharashtra | I4: business_registered_composition | J4: false | K4: 45749 | M4: INR | N4: 1 | O4: item_level | P4: true | Q4: Tax Invoice | R4: 0.00 | U4: entity_level | V4: Technical Fees (2%) | W4: 2.00 | X4: 194J | Y4: Section 194 J | Z4: 19872.000 | AA4: 993600 | AB4: 1152576 | AC4: 0 | AD4: 0 | AE4: Adjustment | AG4: 45762 | AH4: 0 | AI4: Due On Receipt | AJ4: Thanks for your business. | AT4: Invoice | AU4: 0.0 | AV4: 0 | BD4: Jurisphere Enterprise Subscription | BE4: Duration - 6 months Subscriptions Description- 46 licenses of Rs. 4000 per month per license | BF4: 46 | BG4: 10.00 | BH4: 110400.000 | BI4: 993600 | BJ4: pcs | BK4: 24000 | BL4: 2297152000000039748 | BQ4: Tushar Raut | BR4: 1st Floor, Veritas Legal, Forbes Building, | BS4: Charanjit Rai Marg, Azad Maidan, Fort, | BT4: Mumbai | BU4: Maharashtra | BV4: India | BW4: 400001 | BX4: +91-22-43686700 | BZ4: Tushar Raut | CA4: 1st Floor, Veritas Legal, Forbes Building, | CB4: Charanjit Rai Marg, Azad Maidan, Fort, | CC4: Mumbai | CD4: Maharashtra | CE4: India | CF4: 400001 | CH4: +91-22-43686700 | CI4: Coresphere100 Technologies Pvt. Ltd. | CJ4: 09AALCC7037K1Z7 | CK4: 16026, 16th Floor, Tower Oakwood, | CL4: Greater Noida, | CM4: Uttar Pradesh | CN4: India | CO4: 201306 | CP4: 8928163657 | CQ4: manas@jurisphere.ai | CR4: 0.00 | CS4: 0.00 | CT4: 18.00 | CU4: 0.00 | CV4: 0.00 | CW4: 0.00 | CX4: 178848.00 | CY4: 0.00 | CZ4: 0.00 | DA4: 0.00 | DB4: 178848.00 | DC4: 0.00 | DL4: 27AANFV0524F1Z7 | DP4: 998313 | DQ4: 0 | DT4: tushar.raut@veritaslegal.in | DV4: +91-22-43686700 | DX4: service | EH4: Others | EK4: Sales | EM4: Taxable | EN4: 2297152000000031111 | EO4: IGST18 | EP4: 18.00 | EQ4: 178848 | ER4: ItemAmount
A5: 45749 | B5: 2297152000000051047 | C5: INV-25-26-000004 | D5: Closed | E5: 2297152000000051029 | F5: LEGALOGIC CONSULTING LLP | G5: MH | H5: 27-Maharashtra | I5: business_gst | J5: false | K5: 45749 | M5: INR | N5: 1 | O5: item_level | P5: true | Q5: Tax Invoice | R5: 0.00 | U5: entity_level | V5: Professional Fees | W5: 10.00 | X5: 194J | Y5: Section 194 J | Z5: 3000.000 | AA5: 30000 | AB5: 32400 | AC5: 0 | AD5: 0 | AE5: Adjustment | AG5: 45752 | AH5: 0 | AI5: Due On Receipt | AJ5: Thanks for your business. | AT5: Invoice | AU5: 0.0 | AV5: 0 | BD5: Jurisphere Enterprise Subscription | BE5: Subscription Period : monthly invoice 01 April 2025 to 30 June, 2025 Unlimited Access- Enterprise Tool (for 15 users) | BF5: 1 | BG5: 0.00 | BH5: 0.00 | BI5: 30000 | BJ5: pcs | BK5: 30000 | BL5: 2297152000000039748 | BR5: Unit No.3A, PV House, FP No. 85, | BS5: T.P. Scheme No. 1 55, Damle Road, Erandwane | BT5: Pune | BU5: Maharashtra | BV5: India | BW5: 411004 | CA5: Unit No.3A, PV House, FP No. 85, | CB5: T.P. Scheme No. 1 55, Damle Road, Erandwane | CC5: Pune | CD5: Maharashtra | CE5: India | CF5: 411004 | CI5: Coresphere100 Technologies Pvt. Ltd. | CJ5: 09AALCC7037K1Z7 | CK5: 16026, 16th Floor, Tower Oakwood, | CL5: Greater Noida, | CM5: Uttar Pradesh | CN5: India | CO5: 201306 | CP5: 8928163657 | CQ5: manas@jurisphere.ai | CR5: 0.00 | CS5: 0.00 | CT5: 18.00 | CU5: 0.00 | CV5: 0.00 | CW5: 0.00 | CX5: 5400.00 | CY5: 0.00 | CZ5: 0.00 | DA5: 0.00 | DB5: 5400.00 | DC5: 0.00 | DL5: 27AAFFL6917J1ZZ | DP5: 998313 | DQ5: 0 | DX5: service | EH5: Others | EK5: Sales | EM5: Taxable | EN5: 2297152000000031111 | EO5: IGST18 | EP5: 18.00 | EQ5: 5400 | ER5: ItemAmount
A6: 45750 | B6: 2297152000000051071 | C6: INV-25-26-000005 | D6: Overdue | E6: 2297152000000051011 | F6: VACUITAS COUNSELLOR LLP | G6: WB | H6: 19-West Bengal | I6: business_gst | J6: false | K6: 45750 | M6: INR | N6: 1 | O6: item_level | P6: true | Q6: Tax Invoice | R6: 0.00 | U6: item_level | W6: 0.00 | Z6: 0.000 | AA6: 99000 | AB6: 116820 | AC6: 116820 | AD6: 0 | AE6: Adjustment | AH6: 0 | AI6: Due On Receipt | AJ6: Thanks for your business. | AT6: Invoice | AU6: 0.0 | AV6: 0 | BD6: Jurisphere Enterprise Subscription | BE6: Subscription Period- 1 year Description- Unlimited Tool for 2 logins | BF6: 2 | BG6: 0.00 | BH6: 0.00 | BI6: 99000 | BJ6: pcs | BK6: 49500 | BL6: 2297152000000039748 | BR6: 6, Brabourne Road, | BT6: Kolkata | BU6: West Bengal | BV6: India | BW6: 700001 | CA6: 6, Brabourne Road, | CC6: Kolkata | CD6: West Bengal | CE6: India | CF6: 700001 | CI6: Coresphere100 Technologies Pvt. Ltd. | CJ6: 09AALCC7037K1Z7 | CK6: 16026, 16th Floor, Tower Oakwood, | CL6: Greater Noida, | CM6: Uttar Pradesh | CN6: India | CO6: 201306 | CP6: 8928163657 | CQ6: manas@jurisphere.ai | CR6: 0.00 | CS6: 0.00 | CT6: 18.00 | CU6: 0.00 | CV6: 0.00 | CW6: 0.00 | CX6: 17820.00 | CY6: 0.00 | CZ6: 0.00 | DA6: 0.00 | DB6: 17820.00 | DC6: 0.00 | DI6: 0.000 | DL6: 19AAVFV8769L1ZO | DP6: 998313 | DQ6: 0 | DX6: service | EH6: Others | EK6: Sales | EM6: Taxable | EN6: 2297152000000031111 | EO6: IGST18 | EP6: 18.00 | EQ6: 17820 | ER6: ItemAmount
A7: 45752 | B7: 2297152000000053035 | C7: INV-25-26-000006 | D7: Closed | E7: 2297152000000053017 | F7: Tvashta Law | G7: DL | H7: 07-Delhi | I7: business_none | J7: false | K7: 45752 | M7: INR | N7: 1 | O7: item_level | P7: true | Q7: Tax Invoice | R7: 0.00 | U7: item_level | W7: 0.00 | Z7: 0.000 | AA7: 2000 | AB7: 2360 | AC7: 0 | AD7: 0 | AE7: Adjustment | AG7: 45752 | AH7: 0 | AI7: Due On Receipt | AJ7: Thanks for your business. | AT7: Invoice | AU7: 0.0 | AV7: 0 | BD7: Jurisphere Enterprise Subscription | BE7: Description - 10 credits for MCA of INR 200/credit | BF7: 10 | BG7: 0.00 | BH7: 0.00 | BI7: 2000 | BJ7: pcs | BK7: 200 | BL7: 2297152000000039748 | BR7: C 36 Lower Ground Floor, | BS7: Mayfair Gardens, | BT7: New Delhi | BU7: Delhi | BV7: India | BW7: 110019 | CA7: C 36 Lower Ground Floor, | CB7: Mayfair Gardens, | CC7: New Delhi | CD7: Delhi | CE7: India | CF7: 110019 | CI7: Coresphere100 Technologies Pvt. Ltd. | CJ7: 09AALCC7037K1Z7 | CK7: 16026, 16th Floor, Tower Oakwood, | CL7: Greater Noida, | CM7: Uttar Pradesh | CN7: India | CO7: 201306 | CP7: 8928163657 | CQ7: manas@jurisphere.ai | CR7: 0.00 | CS7: 0.00 | CT7: 18.00 | CU7: 0.00 | CV7: 0.00 | CW7: 0.00 | CX7: 360.00 | CY7: 0.00 | CZ7: 0.00 | DA7: 0.00 | DB7: 360.00 | DC7: 0.00 | DI7: 0.000 | DP7: 998313 | DQ7: 0 | DX7: service | EH7: Others | EK7: Sales | EM7: Taxable | EN7: 2297152000000031111 | EO7: IGST18 | EP7: 18.00 | EQ7: 360 | ER7: ItemAmount
A8: 45754 | B8: 2297152000000054231 | C8: INV-25-26-000007 | D8: Closed | E8: 2297152000000054193 | F8: U. S. GANDHI & CO. | G8: MH | H8: 27-Maharashtra | I8: business_gst | J8: false | K8: 45754 | M8: INR | N8: 1 | O8: item_level | P8: true | Q8: Tax Invoice | R8: 0.00 | U8: item_level | W8: 0.00 | Z8: 0.000 | AA8: 8000 | AB8: 9440 | AC8: 0 | AD8: 0 | AE8: Adjustment | AG8: 45754 | AH8: 0 | AI8: Due On Receipt | AJ8: Thanks for your business. | AT8: Invoice | AU8: 0.0 | AV8: 0 | BD8: Jurisphere Enterprise Subscription | BE8: Description - Unlimited usage of 1 license for 2 months for Rs.4000/month | BF8: 1 | BG8: 0.00 | BH8: 0.00 | BI8: 8000 | BJ8: pcs | BK8: 8000 | BL8: 2297152000000039748 | BR8: 2ND FLOOR, 114, SUNDERVILLA, SV ROAD, | BS8: NEXT TO VIJAY SALES, SANTACRUZ WEST, Mumbai Suburban, | BT8: Mumbai | BU8: Maharashtra | BV8: India | BW8: 400054 | CA8: 2ND FLOOR, 114, SUNDERVILLA, SV ROAD, | CB8: NEXT TO VIJAY SALES, SANTACRUZ WEST, Mumbai Suburban, | CC8: Mumbai | CD8: Maharashtra | CE8: India | CF8: 400054 | CI8: Coresphere100 Technologies Pvt. Ltd. | CJ8: 09AALCC7037K1Z7 | CK8: 16026, 16th Floor, Tower Oakwood, | CL8: Greater Noida, | CM8: Uttar Pradesh | CN8: India | CO8: 201306 | CP8: 8928163657 | CQ8: manas@jurisphere.ai | CR8: 0.00 | CS8: 0.00 | CT8: 18.00 | CU8: 0.00 | CV8: 0.00 | CW8: 0.00 | CX8: 1440.00 | CY8: 0.00 | CZ8: 0.00 | DA8: 0.00 | DB8: 1440.00 | DC8: 0.00 | DI8: 0.000 | DL8: 27AACFU5143J1Z1 | DP8: 998313 | DQ8: 0 | DX8: service | EH8: Others | EK8: Sales | EM8: Taxable | EN8: 2297152000000031111 | EO8: IGST18 | EP8: 18.00 | EQ8: 1440 | ER8: ItemAmount
A9: 45754 | B9: 2297152000000054324 | C9: INV-25-26-000008 | D9: Closed | E9: 2297152000000061001 | F9: B2C | G9: UP | H9: 09-Uttar Pradesh | I9: business_none | J9: false | K9: 45754 | M9: INR | N9: 1 | O9: item_level | P9: true | Q9: Tax Invoice | R9: 0.00 | U9: item_level | W9: 0.00 | Z9: 0.000 | AA9: 12277.12 | AB9: 14487 | AC9: 0 | AD9: 0 | AE9: Adjustment | AG9: 45754 | AH9: 0 | AI9: Due On Receipt | AJ9: Thanks for your business. | AT9: Invoice | AU9: 0.0 | AV9: 0 | BD9: Jurisphere Enterprise Subscription | BE9: Razorpay B2C sales from 1st Apr to 7th Apr 25 | BF9: 1 | BG9: 0.00 | BH9: 0.00 | BI9: 12277.12 | BJ9: pcs | BK9: 12277.12 | BL9: 2297152000000039748 | CI9: Coresphere100 Technologies Pvt. Ltd. | CJ9: 09AALCC7037K1Z7 | CK9: 16026, 16th Floor, Tower Oakwood, | CL9: Greater Noida, | CM9: Uttar Pradesh | CN9: India | CO9: 201306 | CP9: 8928163657 | CQ9: manas@jurisphere.ai | CR9: 9.00 | CS9: 9.00 | CT9: 0.00 | CU9: 0.00 | CV9: 1104.94 | CW9: 1104.94 | CX9: 0.00 | CY9: 0.00 | CZ9: 1104.94 | DA9: 1104.94 | DB9: 0.00 | DC9: 0.00 | DI9: 0.000 | DP9: 998313 | DQ9: 0 | DX9: service | EH9: Others | EK9: Sales | EM9: Taxable | EN9: 2297152000000031213 | EO9: GST18 | EP9: 18.00 | EQ9: 2209.88 | ER9: Tax Group
A10: 45754 | B10: 2297152000000054375 | C10: INV-25-26-000009 | D10: Closed | E10: 2297152000000054306 | F10: Advocate Rohit Jaiswal | G10: UP | H10: 09-Uttar Pradesh | I10: business_none | J10: false | K10: 45754 | M10: INR | N10: 1 | O10: item_level | P10: true | Q10: Tax Invoice | R10: 0.00 | U10: item_level | W10: 0.00 | Z10: 0.000 | AA10: 5000 | AB10: 5900 | AC10: 0 | AD10: 0 | AE10: Adjustment | AG10: 45754 | AH10: 0 | AI10: Due On Receipt | AJ10: Thanks for your business. | AT10: Invoice | AU10: 0.0 | AV10: 0 | BD10: Jurisphere Enterprise Subscription | BE10: Subscription- Monthly for the period started from April 15, 2025 to April 14, 2026 Description- 1 License for INR 5000 | BF10: 1 | BG10: 0.00 | BH10: 0.000 | BI10: 5000 | BJ10: pcs | BK10: 5000 | BL10: 2297152000000039748 | BP10: Advocate Rohit Jaiswal | BT10: Lucknow | BU10: Uttar Pradesh | BV10: India | CC10: Lucknow | CD10: Uttar Pradesh | CE10: India | CI10: Coresphere100 Technologies Pvt. Ltd. | CJ10: 09AALCC7037K1Z7 | CK10: 16026, 16th Floor, Tower Oakwood, | CL10: Greater Noida, | CM10: Uttar Pradesh | CN10: India | CO10: 201306 | CP10: 8928163657 | CQ10: manas@jurisphere.ai | CR10: 9.00 | CS10: 9.00 | CT10: 0.00 | CU10: 0.00 | CV10: 450.00 | CW10: 450.00 | CX10: 0.00 | CY10: 0.00 | CZ10: 450.00 | DA10: 450.00 | DB10: 0.00 | DC10: 0.00 | DI10: 0.000 | DP10: 998313 | DQ10: 0 | DX10: service | EH10: Others | EK10: Sales | EM10: Taxable | EN10: 2297152000000031213 | EO10: GST18 | EP10: 18.00 | EQ10: 900 | ER10: Tax Group
A11: 45755 | B11: 2297152000000054400 | C11: INV-25-26-000010 | D11: Overdue | E11: 2297152000000054432 | F11: Dileep Poolakkot | G11: DL | H11: 07-Delhi | I11: business_none | J11: false | K11: 45755 | M11: INR | N11: 1 | O11: item_level | P11: true | Q11: Tax Invoice | R11: 0.00 | U11: item_level | W11: 0.00 | Z11: 0.000 | AA11: 60004 | AB11: 70804.72 | AC11: 4.72 | AD11: 0 | AE11: Adjustment | AG11: 45756 | AH11: 0 | AI11: Due On Receipt | AJ11: Thanks for your business. | AT11: Invoice | AU11: 0.0 | AV11: 0 | BD11: Jurisphere Enterprise Subscription | BE11: Subscription- Annual Subscription from 8th April 2025 Description- 1 License for INR 60000 | BF11: 1 | BG11: 14.28 | BH11: 9996.000 | BI11: 60004 | BJ11: pcs | BK11: 70000 | BL11: 2297152000000039748 | BP11: Advocate Rohit Jaiswal | BR11: 251, Tower-5, | BS11: Supreme Enclave, Mayur Vihar-1, | BT11: Delhi | BU11: Delhi | BV11: India | BW11: 110091 | CA11: 251, Tower-5, | CB11: Supreme Enclave, Mayur Vihar-1, | CC11: Delhi | CD11: Delhi | CE11: India | CF11: 110091 | CI11: Coresphere100 Technologies Pvt. Ltd. | CJ11: 09AALCC7037K1Z7 | CK11: 16026, 16th Floor, Tower Oakwood, | CL11: Greater Noida, | CM11: Uttar Pradesh | CN11: India | CO11: 201306 | CP11: 8928163657 | CQ11: manas@jurisphere.ai | CR11: 0.00 | CS11: 0.00 | CT11: 18.00 | CU11: 0.00 | CV11: 0.00 | CW11: 0.00 | CX11: 10800.72 | CY11: 0.00 | CZ11: 0.00 | DA11: 0.00 | DB11: 10800.72 | DC11: 0.00 | DI11: 0.000 | DP11: 998313 | DQ11: 0 | DX11: service | EH11: Others | EK11: Sales | EM11: Taxable | EN11: 2297152000000031111 | EO11: IGST18 | EP11: 18.00 | EQ11: 10800.72 | ER11: ItemAmount
A12: 45755 | B12: 2297152000000054492 | C12: INV-25-26-000011 | D12: Closed | E12: 2297152000000054474 | F12: Utkarsh Joshi | G12: DL | H12: 07-Delhi | I12: business_none | J12: false | K12: 45755 | M12: INR | N12: 1 | O12: item_level | P12: true | Q12: Tax Invoice | R12: 0.00 | U12: item_level | W12: 0.00 | Z12: 0.000 | AA12: 6000 | AB12: 7080 | AC12: 0 | AD12: 0 | AE12: Adjustment | AG12: 45755 | AH12: 0 | AI12: Due On Receipt | AJ12: Thanks for your business. | AT12: Invoice | AU12: 0.0 | AV12: 0 | BD12: Jurisphere Enterprise Subscription | BE12: Subscription- 2 Months Contract Description- 1 License for INR 3000/month. Customer may opt-out out of the contract with a pro-rata refund at anytime during the duration of the contract. | BF12: 1 | BG12: 0.00 | BH12: 0.00 | BI12: 6000 | BJ12: pcs | BK12: 6000 | BL12: 2297152000000039748 | BR12: Ground Floor, S-456, | BS12: GK 2, | BT12: Delhi | BU12: Delhi | BV12: India | BW12: 110048 | CA12: Ground Floor, S-456, | CB12: GK 2, | CC12: Delhi | CD12: Delhi | CE12: India | CF12: 110048 | CI12: Coresphere100 Technologies Pvt. Ltd. | CJ12: 09AALCC7037K1Z7 | CK12: 16026, 16th Floor, Tower Oakwood, | CL12: Greater Noida, | CM12: Uttar Pradesh | CN12: India | CO12: 201306 | CP12: 8928163657 | CQ12: manas@jurisphere.ai | CR12: 0.00 | CS12: 0.00 | CT12: 18.00 | CU12: 0.00 | CV12: 0.00 | CW12: 0.00 | CX12: 1080.00 | CY12: 0.00 | CZ12: 0.00 | DA12: 0.00 | DB12: 1080.00 | DC12: 0.00 | DI12: 0.000 | DP12: 998313 | DQ12: 0 | DX12: service | EH12: Others | EK12: Sales | EM12: Taxable | EN12: 2297152000000031111 | EO12: IGST18 | EP12: 18.00 | EQ12: 1080 | ER12: ItemAmount
A13: 45755 | B13: 2297152000000054539 | C13: INV-25-26-000012 | D13: Closed | E13: 2297152000000054510 | F13: Karan Butalia | G13: DL | H13: 07-Delhi | I13: business_gst | J13: false | K13: 45755 | M13: INR | N13: 1 | O13: item_level | P13: true | Q13: Tax Invoice | R13: 0.00 | U13: item_level | W13: 0.00 | Z13: 0.000 | AA13: 4000 | AB13: 4720 | AC13: 0 | AD13: 0 | AE13: Adjustment | AG13: 45755 | AH13: 0 | AI13: Due On Receipt | AJ13: Thanks for your business. | AT13: Invoice | AU13: 0.0 | AV13: 0 | BD13: Jurisphere Enterprise Subscription | BE13: Subscription Period- 2 months Description- 1 login of INR 4000 for 2 months, Only for document Review and Research | BF13: 1 | BG13: 0.00 | BH13: 0.00 | BI13: 4000 | BJ13: pcs | BK13: 4000 | BL13: 2297152000000039748 | BR13: 75, Qutab View Apartments, | BS13: Katwaria Sarai, | BT13: New Delhi | BU13: Delhi | BV13: India | BW13: 110016 | CA13: 75, Qutab View Apartments, | CB13: Katwaria Sarai, | CC13: New Delhi | CD13: Delhi | CE13: India | CF13: 110016 | CI13: Coresphere100 Technologies Pvt. Ltd. | CJ13: 09AALCC7037K1Z7 | CK13: 16026, 16th Floor, Tower Oakwood, | CL13: Greater Noida, | CM13: Uttar Pradesh | CN13: India | CO13: 201306 | CP13: 8928163657 | CQ13: manas@jurisphere.ai | CR13: 0.00 | CS13: 0.00 | CT13: 18.00 | CU13: 0.00 | CV13: 0.00 | CW13: 0.00 | CX13: 720.00 | CY13: 0.00 | CZ13: 0.00 | DA13: 0.00 | DB13: 720.00 | DC13: 0.00 | DI13: 0.000 | DL13: 07AEGPB1913B1ZC | DP13: 998313 | DQ13: 0 | DX13: service | EH13: Others | EK13: Sales | EM13: Taxable | EN13: 2297152000000031111 | EO13: IGST18 | EP13: 18.00 | EQ13: 720 | ER13: ItemAmount
A14: 45755 | B14: 2297152000000054571 | C14: INV-25-26-000013 | D14: Overdue | E14: 2297152000000054553 | F14: Agama Law Associates | G14: MH | H14: 27-Maharashtra | I14: business_none | J14: false | K14: 45755 | M14: INR | N14: 1 | O14: item_level | P14: true | Q14: Tax Invoice | R14: 0.00 | U14: entity_level | V14: Technical Fees (2%) | W14: 2.00 | X14: 194J | Y14: Section 194 J | Z14: 1355.940 | AA14: 67797 | AB14: 78644.06 | AC14: 1356.06 | AD14: -0.46 | AE14: Adjustment | AG14: 45757 | AH14: 0 | AI14: Due On Receipt | AJ14: Thanks for your business. | AT14: Invoice | AU14: 0.0 | AV14: 0 | BD14: Jurisphere Enterprise Subscription | BE14: Subscription Period- 1st April, 2025 to 30th June, 2025 | BF14: 1 | BG14: 0.00 | BH14: 0.00 | BI14: 67797 | BJ14: pcs | BK14: 67797 | BL14: 2297152000000039748 | BQ14: Nitin Jain | BR14: 13th Floor Oppt, MTNL Office, Lodha Supremus, | BS14: 1301, Saki Vihar Rd, Tunga Village, Chandivali, Powai, | BT14: Mumbai | BU14: Maharashtra | BV14: India | BW14: 400072 | BZ14: Nitin Jain | CA14: 13th Floor Oppt, MTNL Office, Lodha Supremus, | CB14: 1301, Saki Vihar Rd, Tunga Village, Chandivali, Powai, | CC14: Mumbai | CD14: Maharashtra | CE14: India | CF14: 400072 | CI14: Coresphere100 Technologies Pvt. Ltd. | CJ14: 09AALCC7037K1Z7 | CK14: 16026, 16th Floor, Tower Oakwood, | CL14: Greater Noida, | CM14: Uttar Pradesh | CN14: India | CO14: 201306 | CP14: 8928163657 | CQ14: manas@jurisphere.ai | CR14: 0.00 | CS14: 0.00 | CT14: 18.00 | CU14: 0.00 | CV14: 0.00 | CW14: 0.00 | CX14: 12203.46 | CY14: 0.00 | CZ14: 0.00 | DA14: 0.00 | DB14: 12203.46 | DC14: 0.00 | DP14: 998313 | DQ14: 0 | DT14: nitin@agamalaw.com | DU14: 7506122343 | DV14: 022-40229129 | DX14: service | EH14: Others | EK14: Sales | EM14: Taxable | EN14: 2297152000000031111 | EO14: IGST18 | EP14: 18.00 | EQ14: 12203.46 | ER14: ItemAmount
A15: 45755 | B15: 2297152000000054775 | C15: INV-25-26-000014 | D15: Closed | E15: 2297152000000054757 | F15: RAJANI ASSOCIATES | G15: MH | H15: 27-Maharashtra | I15: business_gst | J15: false | K15: 45755 | M15: INR | N15: 1 | O15: item_level | P15: true | Q15: Tax Invoice | R15: 0.00 | U15: item_level | W15: 0.00 | Z15: 0.000 | AA15: 21000 | AB15: 24780 | AC15: 0 | AD15: 0 | AE15: Adjustment | AG15: 45757 | AH15: 0 | AI15: Due On Receipt | AJ15: Thanks for your business. | AT15: Invoice | AU15: 0.0 | AV15: 0 | BD15: Jurisphere Enterprise Subscription | BE15: Subscription Period- 1 month started from 10th April, 2025 to 9th May, 2025 Description - 3 License for Rs. 7000 each for per month | BF15: 3 | BG15: 0.00 | BH15: 0.00 | BI15: 21000 | BJ15: pcs | BK15: 7000 | BL15: 2297152000000039748 | BQ15: RIshi Rajani | BR15: 204-207, Krishna Chambers, | BS15: 59 New Marine Lines, Churchgate, | BT15: Mumbai, | BU15: Maharashtra | BV15: India | BW15: 400020 | BZ15: RIshi Rajani | CA15: 204-207, Krishna Chambers, | CB15: 59 New Marine Lines, Churchgate, | CC15: Mumbai, | CD15: Maharashtra | CE15: India | CF15: 400020 | CI15: Coresphere100 Technologies Pvt. Ltd. | CJ15: 09AALCC7037K1Z7 | CK15: 16026, 16th Floor, Tower Oakwood, | CL15: Greater Noida, | CM15: Uttar Pradesh | CN15: India | CO15: 201306 | CP15: 8928163657 | CQ15: manas@jurisphere.ai | CR15: 0.00 | CS15: 0.00 | CT15: 18.00 | CU15: 0.00 | CV15: 0.00 | CW15: 0.00 | CX15: 3780.00 | CY15: 0.00 | CZ15: 0.00 | DA15: 0.00 | DB15: 3780.00 | DC15: 0.00 | DI15: 0.000 | DL15: 27AANFR0363C1ZC | DP15: 998313 | DQ15: 0 | DT15: rishi@rajaniassociates.net | DX15: service | EH15: Others | EK15: Sales | EM15: Taxable | EN15: 2297152000000031111 | EO15: IGST18 | EP15: 18.00 | EQ15: 3780 | ER15: ItemAmount
A16: 45756 | B16: 2297152000000060019 | C16: INV-25-26-000015 | D16: Closed | E16: 2297152000000060001 | F16: Venkatesh Dhond | G16: UP | H16: 09-Uttar Pradesh | I16: business_none | J16: false | K16: 45756 | M16: INR | N16: 1 | O16: item_level | P16: true | Q16: Tax Invoice | R16: 0.00 | U16: item_level | W16: 0.00 | Z16: 0.000 | AA16: 85500 | AB16: 100890 | AC16: 0 | AD16: 0 | AE16: Adjustment | AG16: 45762 | AH16: 0 | AI16: Due On Receipt | AJ16: Thanks for your business. | AT16: Invoice | AU16: 0.0 | AV16: 0 | BD16: Jurisphere Enterprise Subscription | BE16: Subscription Period- 28 February , 2025 to 27 August, 2025 | BF16: 1 | BG16: 5.00 | BH16: 4500.000 | BI16: 85500 | BJ16: pcs | BK16: 90000 | BL16: 2297152000000039748 | CI16: Coresphere100 Technologies Pvt. Ltd. | CJ16: 09AALCC7037K1Z7 | CK16: 16026, 16th Floor, Tower Oakwood, | CL16: Greater Noida, | CM16: Uttar Pradesh | CN16: India | CO16: 201306 | CP16: 8928163657 | CQ16: manas@jurisphere.ai | CR16: 9.00 | CS16: 9.00 | CT16: 0.00 | CU16: 0.00 | CV16: 7695.00 | CW16: 7695.00 | CX16: 0.00 | CY16: 0.00 | CZ16: 7695.00 | DA16: 7695.00 | DB16: 0.00 | DC16: 0.00 | DI16: 0.000 | DP16: 998313 | DQ16: 0 | DX16: service | EH16: Others | EK16: Sales | EM16: Taxable | EN16: 2297152000000031213 | EO16: GST18 | EP16: 18.00 | EQ16: 15390 | ER16: Tax Group
